<?xml version="1.0" encoding="utf-8"?>
<!-- This URDF was automatically created by SolidWorks to URDF Exporter! Originally created by Stephen Brawner (brawner@gmail.com) 
     Commit Version: 1.5.1-0-g916b5db  Build Version: 1.5.7152.31018
     For more information, please see http://wiki.ros.org/sw_urdf_exporter -->
<robot
  name="snake">
  <link
    name="head_link">
    <inertial>
      <origin
        xyz="-0.0210341207555037 0.00112565983272195 -0.014562552701889"
        rpy="0 0 0" />
      <mass
        value="0.113792447150302" />
      <inertia
        ixx="4.71195529325612E-05"
        ixy="4.89501723380327E-07"
        ixz="-5.83279523791956E-07"
        iyy="6.79376359219111E-05"
        iyz="-3.80325575740942E-07"
        izz="9.53902308389003E-05" />
    </inertial>
    <visual>
      <origin
        xyz="0 0 0"
        rpy="0 0 0" />
      <geometry>
        <mesh
          filename="package://vehicle_simulator/meshes/head_link.STL" />
      </geometry>
      <material
        name="">
        <color
          rgba="1 1 1 1" />
      </material>
    </visual>
    <collision>
      <origin
        xyz="0 0 0"
        rpy="0 0 0" />
      <geometry>
        <mesh
          filename="package://vehicle_simulator/meshes/head_link.STL" />
      </geometry>
    </collision>
  </link>
  <link
    name="one_Link">
    <inertial>
      <origin
        xyz="-0.0261374423990424 0.0181381995761569 0.0737634237352624"
        rpy="0 0 0" />
      <mass
        value="0.0898526627815787" />
      <inertia
        ixx="4.29139495303509E-05"
        ixy="2.12529456312919E-06"
        ixz="-1.36090013175355E-07"
        iyy="2.42273964797253E-05"
        iyz="2.43995206344107E-09"
        izz="4.59997117020137E-05" />
    </inertial>
    <visual>
      <origin
        xyz="0 0 0"
        rpy="0 0 0" />
      <geometry>
        <mesh
          filename="package://vehicle_simulator/meshes/one_Link.STL" />
      </geometry>
      <material
        name="">
        <color
          rgba="0.752941176470588 0.752941176470588 0.752941176470588 1" />
      </material>
    </visual>
    <collision>
      <origin
        xyz="0 0 0"
        rpy="0 0 0" />
      <geometry>
        <mesh
          filename="package://vehicle_simulator/meshes/one_Link.STL" />
      </geometry>
    </collision>
  </link>
  <joint
    name="one_Link_joint"
    type="fixed">
    <origin
      xyz="-0.046558 -0.13232 -0.019069"
      rpy="1.5598 0 3.1416" />
    <parent
      link="head_link" />
    <child
      link="one_Link" />
    <axis
      xyz="0 0 0" />
  </joint>
  <link
    name="two_Link">
    <inertial>
      <origin
        xyz="-0.0169742433347544 -0.00397881287180141 0.0575523514483724"
        rpy="0 0 0" />
      <mass
        value="0.0898527299044515" />
      <inertia
        ixx="4.29139660773669E-05"
        ixy="-2.12530442412568E-06"
        ixz="1.36033148205894E-07"
        iyy="2.42303486022908E-05"
        iyz="-2.41861425190835E-07"
        izz="4.59967882733245E-05" />
    </inertial>
    <visual>
      <origin
        xyz="0 0 0"
        rpy="0 0 0" />
      <geometry>
        <mesh
          filename="package://vehicle_simulator/meshes/two_Link.STL" />
      </geometry>
      <material
        name="">
        <color
          rgba="0.752941176470588 0.752941176470588 0.752941176470588 1" />
      </material>
    </visual>
    <collision>
      <origin
        xyz="0 0 0"
        rpy="0 0 0" />
      <geometry>
        <mesh
          filename="package://vehicle_simulator/meshes/two_Link.STL" />
      </geometry>
    </collision>
  </link>
  <joint
    name="two_Link_joint"
    type="fixed">
    <origin
      xyz="-0.0055339 -0.054364 0.0049055"
      rpy="1.5708 0 0" />
    <parent
      link="head_link" />
    <child
      link="two_Link" />
    <axis
      xyz="0 0 0" />
  </joint>
  <link
    name="three_Link">
    <inertial>
      <origin
        xyz="-0.0169742929136833 -0.00399018985467703 0.0575522707062329"
        rpy="0 0 0" />
      <mass
        value="0.0898526139497692" />
      <inertia
        ixx="4.29139389983036E-05"
        ixy="-2.12529503322531E-06"
        ixz="1.360897425615E-07"
        iyy="2.42273910493052E-05"
        iyz="2.44203743134146E-09"
        izz="4.59996968843322E-05" />
    </inertial>
    <visual>
      <origin
        xyz="0 0 0"
        rpy="0 0 0" />
      <geometry>
        <mesh
          filename="package://vehicle_simulator/meshes/three_Link.STL" />
      </geometry>
      <material
        name="">
        <color
          rgba="0.752941176470588 0.752941176470588 0.752941176470588 1" />
      </material>
    </visual>
    <collision>
      <origin
        xyz="0 0 0"
        rpy="0 0 0" />
      <geometry>
        <mesh
          filename="package://vehicle_simulator/meshes/three_Link.STL" />
      </geometry>
    </collision>
  </link>
  <joint
    name="three_Link_joint"
    type="fixed">
    <origin
      xyz="-0.0055339 -0.10751 0.0049228"
      rpy="1.5708 0 0" />
    <parent
      link="head_link" />
    <child
      link="three_Link" />
    <axis
      xyz="0 0 0" />
  </joint>
  <link
    name="four_Link">
    <inertial>
      <origin
        xyz="-0.016974286940595 -0.00399017844009911 0.0575522684829635"
        rpy="0 0 0" />
      <mass
        value="0.0898526297665168" />
      <inertia
        ixx="4.29139466847454E-05"
        ixy="-2.1252996959293E-06"
        ixz="1.36090067592017E-07"
        iyy="2.42273918932014E-05"
        iyz="2.44245630288262E-09"
        izz="4.59997051482014E-05" />
    </inertial>
    <visual>
      <origin
        xyz="0 0 0"
        rpy="0 0 0" />
      <geometry>
        <mesh
          filename="package://vehicle_simulator/meshes/four_Link.STL" />
      </geometry>
      <material
        name="">
        <color
          rgba="0.752941176470588 0.752941176470588 0.752941176470588 1" />
      </material>
    </visual>
    <collision>
      <origin
        xyz="0 0 0"
        rpy="0 0 0" />
      <geometry>
        <mesh
          filename="package://vehicle_simulator/mesh/four_Link.STL" />
      </geometry>
    </collision>
  </link>
  <joint
    name="four_Link_joint"
    type="fixed">
    <origin
      xyz="-0.0055339 -0.16066 0.0049228"
      rpy="1.5708 0 0" />
    <parent
      link="head_link" />
    <child
      link="four_Link" />
    <axis
      xyz="0 0 0" />
  </joint>
  <link
    name="five_Link">
    <inertial>
      <origin
        xyz="-0.0551386603514624 -0.00086331145722667 0.0697589725928851"
        rpy="0 0 0" />
      <mass
        value="0.0762631923383392" />
      <inertia
        ixx="4.07500907978163E-05"
        ixy="2.1255216968566E-06"
        ixz="-1.48681250389852E-07"
        iyy="2.12535914296474E-05"
        iyz="-2.68421922260312E-08"
        izz="4.39975050456855E-05" />
    </inertial>
    <visual>
      <origin
        xyz="0 0 0"
        rpy="0 0 0" />
      <geometry>
        <mesh
          filename="package://vehicle_simulator/meshes/five_Link.STL" />
      </geometry>
      <material
        name="">
        <color
          rgba="0.752941176470588 0.752941176470588 0.752941176470588 1" />
      </material>
    </visual>
    <collision>
      <origin
        xyz="0 0 0"
        rpy="0 0 0" />
      <geometry>
        <mesh
          filename="package://vehicle_simulator/meshes/five_Link.STL" />
      </geometry>
    </collision>
  </link>
  <joint
    name="five_Link_joint"
    type="fixed">
    <origin
      xyz="-0.075359 -0.3374 -7.193E-05"
      rpy="1.5708 0 3.1416" />
    <parent
      link="head_link" />
    <child
      link="five_Link" />
    <axis
      xyz="0 0 0" />
  </joint>
  <link
    name="tail_Link">
    <inertial>
      <origin
        xyz="-5.35184154646373E-05 -0.000699830656384923 -0.0699097150965293"
        rpy="0 0 0" />
      <mass
        value="0.198681031696659" />
      <inertia
        ixx="0.000225574858006223"
        ixy="4.66948976020826E-09"
        ixz="-8.99109237469229E-08"
        iyy="0.000301334948641655"
        iyz="1.18771992702212E-05"
        izz="0.000148859101209976" />
    </inertial>
    <visual>
      <origin
        xyz="0 0 0"
        rpy="0 0 0" />
      <geometry>
        <mesh
          filename="package://vehicle_simulator/meshes/tail_Link.STL" />
      </geometry>
      <material
        name="">
        <color
          rgba="0.752941176470588 0.752941176470588 0.752941176470588 1" />
      </material>
    </visual>
    <collision>
      <origin
        xyz="0 0 0"
        rpy="0 0 0" />
      <geometry>
        <mesh
          filename="package://vehicle_simulator/meshes/tail_Link.STL" />
      </geometry>
    </collision>
  </link>
  <joint
    name="tail_Link_joint"
    type="continuous">
    <origin
      xyz="-0.021455 -0.28348 0"
      rpy="1.5708 0 -3.1298" />
    <parent
      link="head_link" />
    <child
      link="tail_Link" />
    <axis
      xyz="0 1 0" />
  </joint>
</robot>
